Workbook

Sheet Dataset
A1: Bug_ID | B1: Project | C1: Module | D1: Tester | E1: Severity | F1: Priority | G1: Status | H1: Reported_Date | I1: Resolved_Date | J1: Days_Open | K1: Hours_Spent | L1: Pass_Fail | M1: Environment | N1: Retest_Due | O1: Bug_Description
A2: BUG-001 | B2: Alpha | C2: Login | D2: Alice | E2: Critical | F2: High | G2: Open | H2: 45296 | J2: =IFERROR(IF(G2="Open",TODAY()-H2,I2-H2),"—") -> 896 | K2: 8 | L2: Fail | M2: QA | N2: 45301 | O2: Login button unresponsive on Chrome
A3: BUG-002 | B3: Alpha | C3: Dashboard | D3: Bob | E3: High | F3: High | G3: Resolved | H3: 45297 | I3: 45299 | J3: =IFERROR(IF(G3="Open",TODAY()-H3,I3-H3),"—") -> 2 | K3: 5 | L3: Pass | M3: QA | N3: 45300 | O3: Dashboard loads slowly on first open
A4: BUG-003 | B4: Beta | C4: Reports | D4: Alice | E4: Medium | F4: Medium | G4: Open | H4: 45298 | J4: =IFERROR(IF(G4="Open",TODAY()-H4,I4-H4),"—") -> 894 | K4: 3 | L4: Fail | M4: Staging | N4: 45303 | O4: Export to PDF fails silently
A5: BUG-004 | B5: Beta | C5: Login | D5: Charlie | E5: Low | F5: Low | G5: Closed | H5: 45299 | I5: 45300 | J5: =IFERROR(IF(G5="Open",TODAY()-H5,I5-H5),"—") -> 1 | K5: 2 | L5: Pass | M5: QA | O5: Typo in login error message
A6: BUG-005 | B6: Alpha | C6: Payments | D6: Bob | E6: Critical | F6: High | G6: Resolved | H6: 45300 | I6: 45302 | J6: =IFERROR(IF(G6="Open",TODAY()-H6,I6-H6),"—") -> 2 | K6: 10 | L6: Pass | M6: Production | N6: 45303 | O6: Payment gateway timeout on retry
A7: BUG-006 | B7: Gamma | C7: Search | D7: Diana | E7: High | F7: Medium | G7: Open | H7: 45301 | J7: =IFERROR(IF(G7="Open",TODAY()-H7,I7-H7),"—") -> 891 | K7: 4 | L7: Fail | M7: QA | N7: 45306 | O7: Search returns wrong result set
A8: BUG-007 | B8: Gamma | C8: Reports | D8: Charlie | E8: Medium | F8: Low | G8: Closed | H8: 45302 | I8: 45304 | J8: =IFERROR(IF(G8="Open",TODAY()-H8,I8-H8),"—") -> 2 | K8: 3 | L8: Pass | M8: Staging | O8: Report pagination broken on page 3
A9: BUG-008 | B9: Alpha | C9: Login | D9: Alice | E9: Low | F9: Low | G9: Resolved | H9: 45303 | I9: 45305 | J9: =IFERROR(IF(G9="Open",TODAY()-H9,I9-H9),"—") -> 2 | K9: 2 | L9: Pass | M9: QA | N9: 45306 | O9: Password field asterisks missing
A10: BUG-009 | B10: Beta | C10: Dashboard | D10: Bob | E10: Critical | F10: High | G10: Open | H10: 45304 | J10: =IFERROR(IF(G10="Open",TODAY()-H10,I10-H10),"—") -> 888 | K10: 7 | L10: Fail | M10: Production | N10: 45309 | O10: App crashes on dashboard load
A11: BUG-010 | B11: Beta | C11: Payments | D11: Diana | E11: High | F11: High | G11: Resolved | H11: 45305 | I11: 45307 | J11: =IFERROR(IF(G11="Open",TODAY()-H11,I11-H11),"—") -> 2 | K11: 6 | L11: Pass | M11: QA | N11: 45308 | O11: Double charge on payment retry
A12: BUG-011 | B12: Gamma | C12: Login | D12: Alice | E12: Medium | F12: Medium | G12: Open | H12: 45306 | J12: =IFERROR(IF(G12="Open",TODAY()-H12,I12-H12),"—") -> 886 | K12: 3 | L12: Fail | M12: Staging | N12: 45311 | O12: SSO redirect broken after logout
A13: BUG-012 | B13: Alpha | C13: Search | D13: Charlie | E13: Low | F13: Low | G13: Closed | H13: 45307 | I13: 45308 | J13: =IFERROR(IF(G13="Open",TODAY()-H13,I13-H13),"—") -> 1 | K13: 1 | L13: Pass | M13: QA | O13: Minor UI alignment issue in search bar
A14: BUG-013 | B14: Beta | C14: Search | D14: Bob | E14: Critical | F14: High | G14: Resolved | H14: 45308 | I14: 45310 | J14: =IFERROR(IF(G14="Open",TODAY()-H14,I14-H14),"—") -> 2 | K14: 9 | L14: Pass | M14: Production | N14: 45311 | O14: Search API returns HTTP 500 error
A15: BUG-014 | B15: Gamma | C15: Payments | D15: Diana | E15: High | F15: Medium | G15: Open | H15: 45309 | J15: =IFERROR(IF(G15="Open",TODAY()-H15,I15-H15),"—") -> 883 | K15: 5 | L15: Fail | M15: QA | N15: 45314 | O15: Currency conversion rounding error
A16: BUG-015 | B16: Alpha | C16: Reports | D16: Alice | E16: Medium | F16: Low | G16: Closed | H16: 45310 | I16: 45312 | J16: =IFERROR(IF(G16="Open",TODAY()-H16,I16-H16),"—") -> 2 | K16: 4 | L16: Pass | M16: Staging | O16: Date filter not applying correctly
A17: BUG-016 | B17: Beta | C17: Login | D17: Charlie | E17: Low | F17: Low | G17: Resolved | H17: 45311 | I17: 45313 | J17: =IFERROR(IF(G17="Open",TODAY()-H17,I17-H17),"—") -> 2 | K17: 2 | L17: Pass | M17: QA | N17: 45314 | O17: Remember me checkbox state bug
A18: BUG-017 | B18: Gamma | C18: Dashboard | D18: Bob | E18: Critical | F18: High | G18: Open | H18: 45312 | J18: =IFERROR(IF(G18="Open",TODAY()-H18,I18-H18),"—") -> 880 | K18: 8 | L18: Fail | M18: Production | N18: 45317 | O18: Memory leak on dashboard widget
A19: BUG-018 | B19: Alpha | C19: Payments | D19: Diana | E19: High | F19: High | G19: Resolved | H19: 45313 | I19: 45315 | J19: =IFERROR(IF(G19="Open",TODAY()-H19,I19-H19),"—") -> 2 | K19: 7 | L19: Pass | M19: QA | N19: 45316 | O19: Discount code not applied at checkout
A20: BUG-019 | B20: Beta | C20: Reports | D20: Alice | E20: Medium | F20: Medium | G20: Open | H20: 45314 | J20: =IFERROR(IF(G20="Open",TODAY()-H20,I20-H20),"—") -> 878 | K20: 3 | L20: Fail | M20: Staging | N20: 45319 | O20: CSV export has encoding issue with UTF-8
A21: BUG-020 | B21: Gamma | C21: Search | D21: Charlie | E21: Low | F21: Low | G21: Closed | H21: 45315 | I21: 45316 | J21: =IFERROR(IF(G21="Open",TODAY()-H21,I21-H21),"—") -> 1 | K21: 1 | L21: Pass | M21: QA | O21: Autocomplete flicker on fast typing

Sheet S2_Lookup_Functions
A1: LOOKUP FUNCTIONS | Source: Dataset sheet | Topics: VLOOKUP · HLOOKUP · INDEX · MATCH · OFFSET · INDIRECT
A2: A › VLOOKUP — Find a value in the first column, return a value from another column
A3: Bug_ID (lookup) | B3: Project | C3: Module | D3: Tester | E3: Severity | F3: Status
A4: BUG-001 | B4: =VLOOKUP(A4,Dataset!$A:$O,2,0) -> Alpha | C4: =VLOOKUP(A4,Dataset!$A:$O,3,0) -> Login | D4: =VLOOKUP(A4,Dataset!$A:$O,4,0) -> Alice | E4: =VLOOKUP(A4,Dataset!$A:$O,5,0) -> Critical | F4: =VLOOKUP(A4,Dataset!$A:$O,6,0) -> High
A5: BUG-002 | B5: =VLOOKUP(A5,Dataset!$A:$O,2,0) -> Alpha | C5: =VLOOKUP(A5,Dataset!$A:$O,3,0) -> Dashboard | D5: =VLOOKUP(A5,Dataset!$A:$O,4,0) -> Bob | E5: =VLOOKUP(A5,Dataset!$A:$O,5,0) -> High | F5: =VLOOKUP(A5,Dataset!$A:$O,6,0) -> High
A6: BUG-003 | B6: =VLOOKUP(A6,Dataset!$A:$O,2,0) -> Beta | C6: =VLOOKUP(A6,Dataset!$A:$O,3,0) -> Reports | D6: =VLOOKUP(A6,Dataset!$A:$O,4,0) -> Alice | E6: =VLOOKUP(A6,Dataset!$A:$O,5,0) -> Medium | F6: =VLOOKUP(A6,Dataset!$A:$O,6,0) -> Medium
A7: BUG-004 | B7: =VLOOKUP(A7,Dataset!$A:$O,2,0) -> Beta | C7: =VLOOKUP(A7,Dataset!$A:$O,3,0) -> Login | D7: =VLOOKUP(A7,Dataset!$A:$O,4,0) -> Charlie | E7: =VLOOKUP(A7,Dataset!$A:$O,5,0) -> Low | F7: =VLOOKUP(A7,Dataset!$A:$O,6,0) -> Low
A8: BUG-005 | B8: =VLOOKUP(A8,Dataset!$A:$O,2,0) -> Alpha | C8: =VLOOKUP(A8,Dataset!$A:$O,3,0) -> Payments | D8: =VLOOKUP(A8,Dataset!$A:$O,4,0) -> Bob | E8: =VLOOKUP(A8,Dataset!$A:$O,5,0) -> Critical | F8: =VLOOKUP(A8,Dataset!$A:$O,6,0) -> High
A9: BUG-006 | B9: =VLOOKUP(A9,Dataset!$A:$O,2,0) -> Gamma | C9: =VLOOKUP(A9,Dataset!$A:$O,3,0) -> Search | D9: =VLOOKUP(A9,Dataset!$A:$O,4,0) -> Diana | E9: =VLOOKUP(A9,Dataset!$A:$O,5,0) -> High | F9: =VLOOKUP(A9,Dataset!$A:$O,6,0) -> Medium
A10: BUG-007 | B10: =VLOOKUP(A10,Dataset!$A:$O,2,0) -> Gamma | C10: =VLOOKUP(A10,Dataset!$A:$O,3,0) -> Reports | D10: =VLOOKUP(A10,Dataset!$A:$O,4,0) -> Charlie | E10: =VLOOKUP(A10,Dataset!$A:$O,5,0) -> Medium | F10: =VLOOKUP(A10,Dataset!$A:$O,6,0) -> Low
A11: BUG-008 | B11: =VLOOKUP(A11,Dataset!$A:$O,2,0) -> Alpha | C11: =VLOOKUP(A11,Dataset!$A:$O,3,0) -> Login | D11: =VLOOKUP(A11,Dataset!$A:$O,4,0) -> Alice | E11: =VLOOKUP(A11,Dataset!$A:$O,5,0) -> Low | F11: =VLOOKUP(A11,Dataset!$A:$O,6,0) -> Low
A12: BUG-009 | B12: =VLOOKUP(A12,Dataset!$A:$O,2,0) -> Beta | C12: =VLOOKUP(A12,Dataset!$A:$O,3,0) -> Dashboard | D12: =VLOOKUP(A12,Dataset!$A:$O,4,0) -> Bob | E12: =VLOOKUP(A12,Dataset!$A:$O,5,0) -> Critical | F12: =VLOOKUP(A12,Dataset!$A:$O,6,0) -> High
A13: BUG-010 | B13: =VLOOKUP(A13,Dataset!$A:$O,2,0) -> Beta | C13: =VLOOKUP(A13,Dataset!$A:$O,3,0) -> Payments | D13: =VLOOKUP(A13,Dataset!$A:$O,4,0) -> Diana | E13: =VLOOKUP(A13,Dataset!$A:$O,5,0) -> High | F13: =VLOOKUP(A13,Dataset!$A:$O,6,0) -> High
A14: BUG-011 | B14: =VLOOKUP(A14,Dataset!$A:$O,2,0) -> Gamma | C14: =VLOOKUP(A14,Dataset!$A:$O,3,0) -> Login | D14: =VLOOKUP(A14,Dataset!$A:$O,4,0) -> Alice | E14: =VLOOKUP(A14,Dataset!$A:$O,5,0) -> Medium | F14: =VLOOKUP(A14,Dataset!$A:$O,6,0) -> Medium
A15: BUG-012 | B15: =VLOOKUP(A15,Dataset!$A:$O,2,0) -> Alpha | C15: =VLOOKUP(A15,Dataset!$A:$O,3,0) -> Search | D15: =VLOOKUP(A15,Dataset!$A:$O,4,0) -> Charlie | E15: =VLOOKUP(A15,Dataset!$A:$O,5,0) -> Low | F15: =VLOOKUP(A15,Dataset!$A:$O,6,0) -> Low
... A23: BUG-020 | B23: =VLOOKUP(A23,Dataset!$A:$O,2,0) -> Gamma | C23: =VLOOKUP(A23,Dataset!$A:$O,3,0) -> Search | D23: =VLOOKUP(A23,Dataset!$A:$O,4,0) -> Charlie | E23: =VLOOKUP(A23,Dataset!$A:$O,5,0) -> Low | F23: =VLOOKUP(A23,Dataset!$A:$O,6,0) -> Low
A25: B › INDEX + MATCH — More flexible than VLOOKUP; can look left and use any column
A26: Bug_ID | B26: Hours_Spent | C26: Pass_Fail | D26: Environment | E26: Days_Open | F26: Tester (INDEX+MATCH) | G26: Severity | H26: Priority
A27: BUG-001 | B27: =INDEX(Dataset!$K:$K,MATCH(A27,Dataset!$A:$A,0)) -> 8 | C27: =INDEX(Dataset!$L:$L,MATCH(A27,Dataset!$A:$A,0)) -> Fail | D27: =INDEX(Dataset!$M:$M,MATCH(A27,Dataset!$A:$A,0)) -> QA | E27: =INDEX(Dataset!$J:$J,MATCH(A27,Dataset!$A:$A,0)) -> 896 | F27: =INDEX(Dataset!$D:$D,MATCH(A27,Dataset!$A:$A,0)) -> Alice | G27: =INDEX(Dataset!$E:$E,MATCH(A27,Dataset!$A:$A,0)) -> Critical | H27: =INDEX(Dataset!$F:$F,MATCH(A27,Dataset!$A:$A,0)) -> High
A28: BUG-002 | B28: =INDEX(Dataset!$K:$K,MATCH(A28,Dataset!$A:$A,0)) -> 5 | C28: =INDEX(Dataset!$L:$L,MATCH(A28,Dataset!$A:$A,0)) -> Pass | D28: =INDEX(Dataset!$M:$M,MATCH(A28,Dataset!$A:$A,0)) -> QA | E28: =INDEX(Dataset!$J:$J,MATCH(A28,Dataset!$A:$A,0)) -> 2 | F28: =INDEX(Dataset!$D:$D,MATCH(A28,Dataset!$A:$A,0)) -> Bob | G28: =INDEX(Dataset!$E:$E,MATCH(A28,Dataset!$A:$A,0)) -> High | H28: =INDEX(Dataset!$F:$F,MATCH(A28,Dataset!$A:$A,0)) -> High
A29: BUG-003 | B29: =INDEX(Dataset!$K:$K,MATCH(A29,Dataset!$A:$A,0)) -> 3 | C29: =INDEX(Dataset!$L:$L,MATCH(A29,Dataset!$A:$A,0)) -> Fail | D29: =INDEX(Dataset!$M:$M,MATCH(A29,Dataset!$A:$A,0)) -> Staging | E29: =INDEX(Dataset!$J:$J,MATCH(A29,Dataset!$A:$A,0)) -> 894 | F29: =INDEX(Dataset!$D:$D,MATCH(A29,Dataset!$A:$A,0)) -> Alice | G29: =INDEX(Dataset!$E:$E,MATCH(A29,Dataset!$A:$A,0)) -> Medium | H29: =INDEX(Dataset!$F:$F,MATCH(A29,Dataset!$A:$A,0)) -> Medium
A30: BUG-004 | B30: =INDEX(Dataset!$K:$K,MATCH(A30,Dataset!$A:$A,0)) -> 2 | C30: =INDEX(Dataset!$L:$L,MATCH(A30,Dataset!$A:$A,0)) -> Pass | D30: =INDEX(Dataset!$M:$M,MATCH(A30,Dataset!$A:$A,0)) -> QA | E30: =INDEX(Dataset!$J:$J,MATCH(A30,Dataset!$A:$A,0)) -> 1 | F30: =INDEX(Dataset!$D:$D,MATCH(A30,Dataset!$A:$A,0)) -> Charlie | G30: =INDEX(Dataset!$E:$E,MATCH(A30,Dataset!$A:$A,0)) -> Low | H30: =INDEX(Dataset!$F:$F,MATCH(A30,Dataset!$A:$A,0)) -> Low
A31: BUG-005 | B31: =INDEX(Dataset!$K:$K,MATCH(A31,Dataset!$A:$A,0)) -> 10 | C31: =INDEX(Dataset!$L:$L,MATCH(A31,Dataset!$A:$A,0)) -> Pass | D31: =INDEX(Dataset!$M:$M,MATCH(A31,Dataset!$A:$A,0)) -> Production | E31: =INDEX(Dataset!$J:$J,MATCH(A31,Dataset!$A:$A,0)) -> 2 | F31: =INDEX(Dataset!$D:$D,MATCH(A31,Dataset!$A:$A,0)) -> Bob | G31: =INDEX(Dataset!$E:$E,MATCH(A31,Dataset!$A:$A,0)) -> Critical | H31: =INDEX(Dataset!$F:$F,MATCH(A31,Dataset!$A:$A,0)) -> High
A32: BUG-006 | B32: =INDEX(Dataset!$K:$K,MATCH(A32,Dataset!$A:$A,0)) -> 4 | C32: =INDEX(Dataset!$L:$L,MATCH(A32,Dataset!$A:$A,0)) -> Fail | D32: =INDEX(Dataset!$M:$M,MATCH(A32,Dataset!$A:$A,0)) -> QA | E32: =INDEX(Dataset!$J:$J,MATCH(A32,Dataset!$A:$A,0)) -> 891 | F32: =INDEX(Dataset!$D:$D,MATCH(A32,Dataset!$A:$A,0)) -> Diana | G32: =INDEX(Dataset!$E:$E,MATCH(A32,Dataset!$A:$A,0)) -> High | H32: =INDEX(Dataset!$F:$F,MATCH(A32,Dataset!$A:$A,0)) -> Medium
A33: BUG-007 | B33: =INDEX(Dataset!$K:$K,MATCH(A33,Dataset!$A:$A,0)) -> 3 | C33: =INDEX(Dataset!$L:$L,MATCH(A33,Dataset!$A:$A,0)) -> Pass | D33: =INDEX(Dataset!$M:$M,MATCH(A33,Dataset!$A:$A,0)) -> Staging | E33: =INDEX(Dataset!$J:$J,MATCH(A33,Dataset!$A:$A,0)) -> 2 | F33: =INDEX(Dataset!$D:$D,MATCH(A33,Dataset!$A:$A,0)) -> Charlie | G33: =INDEX(Dataset!$E:$E,MATCH(A33,Dataset!$A:$A,0)) -> Medium | H33: =INDEX(Dataset!$F:$F,MATCH(A33,Dataset!$A:$A,0)) -> Low
A34: BUG-008 | B34: =INDEX(Dataset!$K:$K,MATCH(A34,Dataset!$A:$A,0)) -> 2 | C34: =INDEX(Dataset!$L:$L,MATCH(A34,Dataset!$A:$A,0)) -> Pass | D34: =INDEX(Dataset!$M:$M,MATCH(A34,Dataset!$A:$A,0)) -> QA | E34: =INDEX(Dataset!$J:$J,MATCH(A34,Dataset!$A:$A,0)) -> 2 | F34: =INDEX(Dataset!$D:$D,MATCH(A34,Dataset!$A:$A,0)) -> Alice | G34: =INDEX(Dataset!$E:$E,MATCH(A34,Dataset!$A:$A,0)) -> Low | H34: =INDEX(Dataset!$F:$F,MATCH(A34,Dataset!$A:$A,0)) -> Low
A35: BUG-009 | B35: =INDEX(Dataset!$K:$K,MATCH(A35,Dataset!$A:$A,0)) -> 7 | C35: =INDEX(Dataset!$L:$L,MATCH(A35,Dataset!$A:$A,0)) -> Fail | D35: =INDEX(Dataset!$M:$M,MATCH(A35,Dataset!$A:$A,0)) -> Production | E35: =INDEX(Dataset!$J:$J,MATCH(A35,Dataset!$A:$A,0)) -> 888 | F35: =INDEX(Dataset!$D:$D,MATCH(A35,Dataset!$A:$A,0)) -> Bob | G35: =INDEX(Dataset!$E:$E,MATCH(A35,Dataset!$A:$A,0)) -> Critical | H35: =INDEX(Dataset!$F:$F,MATCH(A35,Dataset!$A:$A,0)) -> High
A36: BUG-010 | B36: =INDEX(Dataset!$K:$K,MATCH(A36,Dataset!$A:$A,0)) -> 6 | C36: =INDEX(Dataset!$L:$L,MATCH(A36,Dataset!$A:$A,0)) -> Pass | D36: =INDEX(Dataset!$M:$M,MATCH(A36,Dataset!$A:$A,0)) -> QA | E36: =INDEX(Dataset!$J:$J,MATCH(A36,Dataset!$A:$A,0)) -> 2 | F36: =INDEX(Dataset!$D:$D,MATCH(A36,Dataset!$A:$A,0)) -> Diana | G36: =INDEX(Dataset!$E:$E,MATCH(A36,Dataset!$A:$A,0)) -> High | H36: =INDEX(Dataset!$F:$F,MATCH(A36,Dataset!$A:$A,0)) -> High
A37: BUG-011 | B37: =INDEX(Dataset!$K:$K,MATCH(A37,Dataset!$A:$A,0)) -> 3 | C37: =INDEX(Dataset!$L:$L,MATCH(A37,Dataset!$A:$A,0)) -> Fail | D37: =INDEX(Dataset!$M:$M,MATCH(A37,Dataset!$A:$A,0)) -> Staging | E37: =INDEX(Dataset!$J:$J,MATCH(A37,Dataset!$A:$A,0)) -> 886 | F37: =INDEX(Dataset!$D:$D,MATCH(A37,Dataset!$A:$A,0)) -> Alice | G37: =INDEX(Dataset!$E:$E,MATCH(A37,Dataset!$A:$A,0)) -> Medium | H37: =INDEX(Dataset!$F:$F,MATCH(A37,Dataset!$A:$A,0)) -> Medium
A38: BUG-012 | B38: =INDEX(Dataset!$K:$K,MATCH(A38,Dataset!$A:$A,0)) -> 1 | C38: =INDEX(Dataset!$L:$L,MATCH(A38,Dataset!$A:$A,0)) -> Pass | D38: =INDEX(Dataset!$M:$M,MATCH(A38,Dataset!$A:$A,0)) -> QA | E38: =INDEX(Dataset!$J:$J,MATCH(A38,Dataset!$A:$A,0)) -> 1 | F38: =INDEX(Dataset!$D:$D,MATCH(A38,Dataset!$A:$A,0)) -> Charlie | G38: =INDEX(Dataset!$E:$E,MATCH(A38,Dataset!$A:$A,0)) -> Low | H38: =INDEX(Dataset!$F:$F,MATCH(A38,Dataset!$A:$A,0)) -> Low
... A46: BUG-020 | B46: =INDEX(Dataset!$K:$K,MATCH(A46,Dataset!$A:$A,0)) -> 1 | C46: =INDEX(Dataset!$L:$L,MATCH(A46,Dataset!$A:$A,0)) -> Pass | D46: =INDEX(Dataset!$M:$M,MATCH(A46,Dataset!$A:$A,0)) -> QA | E46: =INDEX(Dataset!$J:$J,MATCH(A46,Dataset!$A:$A,0)) -> 1 | F46: =INDEX(Dataset!$D:$D,MATCH(A46,Dataset!$A:$A,0)) -> Charlie | G46: =INDEX(Dataset!$E:$E,MATCH(A46,Dataset!$A:$A,0)) -> Low | H46: =INDEX(Dataset!$F:$F,MATCH(A46,Dataset!$A:$A,0)) -> Low
A48: C › OFFSET — Returns a cell/range shifted by rows & cols from a starting point
A49: Bug_ID | B49: Row_Offset | C49: Module (OFFSET) | D49: Severity (OFFSET) | E49: Hours (OFFSET) | F49: Status (OFFSET)
A50: BUG-001 | B50: 2 | C50: =OFFSET(Dataset!$A$1,B50-1,2) -> Login | D50: =OFFSET(Dataset!$A$1,B50-1,4) -> Critical | E50: =OFFSET(Dataset!$A$1,B50-1,10) -> 8 | F50: =OFFSET(Dataset!$A$1,B50-1,6) -> Open
A51: BUG-002 | B51: 3 | C51: =OFFSET(Dataset!$A$1,B51-1,2) -> Dashboard | D51: =OFFSET(Dataset!$A$1,B51-1,4) -> High | E51: =OFFSET(Dataset!$A$1,B51-1,10) -> 5 | F51: =OFFSET(Dataset!$A$1,B51-1,6) -> Resolved
A52: BUG-003 | B52: 4 | C52: =OFFSET(Dataset!$A$1,B52-1,2) -> Reports | D52: =OFFSET(Dataset!$A$1,B52-1,4) -> Medium | E52: =OFFSET(Dataset!$A$1,B52-1,10) -> 3 | F52: =OFFSET(Dataset!$A$1,B52-1,6) -> Open
A53: BUG-004 | B53: 5 | C53: =OFFSET(Dataset!$A$1,B53-1,2) -> Login | D53: =OFFSET(Dataset!$A$1,B53-1,4) -> Low | E53: =OFFSET(Dataset!$A$1,B53-1,10) -> 2 | F53: =OFFSET(Dataset!$A$1,B53-1,6) -> Closed
A54: BUG-005 | B54: 6 | C54: =OFFSET(Dataset!$A$1,B54-1,2) -> Payments | D54: =OFFSET(Dataset!$A$1,B54-1,4) -> Critical | E54: =OFFSET(Dataset!$A$1,B54-1,10) -> 10 | F54: =OFFSET(Dataset!$A$1,B54-1,6) -> Resolved
A55: BUG-006 | B55: 7 | C55: =OFFSET(Dataset!$A$1,B55-1,2) -> Search | D55: =OFFSET(Dataset!$A$1,B55-1,4) -> High | E55: =OFFSET(Dataset!$A$1,B55-1,10) -> 4 | F55: =OFFSET(Dataset!$A$1,B55-1,6) -> Open
A56: BUG-007 | B56: 8 | C56: =OFFSET(Dataset!$A$1,B56-1,2) -> Reports | D56: =OFFSET(Dataset!$A$1,B56-1,4) -> Medium | E56: =OFFSET(Dataset!$A$1,B56-1,10) -> 3 | F56: =OFFSET(Dataset!$A$1,B56-1,6) -> Closed
...

Sheet S3_Logical_Functions
A1: LOGICAL FUNCTIONS | Topics: IF · Nested IF · AND · OR · ISERROR · IFERROR
A2: A › IF — Checks a condition; returns one value if TRUE, another if FALSE
A3: Bug_ID | B3: Status | C3: Priority_Flag | D3: Hours | E3: Effort_Label | F3: Pass_Fail | G3: Result_Emoji
A4: BUG-001 | B4: =VLOOKUP(A4,Dataset!$A:$O,7,0) -> Open | C4: =IF(VLOOKUP(A4,Dataset!$A:$O,6,0)="High","High Priority","Normal") -> High Priority | D4: =VLOOKUP(A4,Dataset!$A:$O,11,0) -> 8 | E4: =IF(D4>=8,"Heavy",IF(D4>=4,"Moderate","Light")) -> Heavy | F4: =VLOOKUP(A4,Dataset!$A:$O,12,0) -> Fail | G4: =IF(F4="Pass","Pass","Fail") -> Fail
A5: BUG-002 | B5: =VLOOKUP(A5,Dataset!$A:$O,7,0) -> Resolved | C5: =IF(VLOOKUP(A5,Dataset!$A:$O,6,0)="High","High Priority","Normal") -> High Priority | D5: =VLOOKUP(A5,Dataset!$A:$O,11,0) -> 5 | E5: =IF(D5>=8,"Heavy",IF(D5>=4,"Moderate","Light")) -> Moderate | F5: =VLOOKUP(A5,Dataset!$A:$O,12,0) -> Pass | G5: =IF(F5="Pass","Pass","Fail") -> Pass
A6: BUG-003 | B6: =VLOOKUP(A6,Dataset!$A:$O,7,0) -> Open | C6: =IF(VLOOKUP(A6,Dataset!$A:$O,6,0)="High","High Priority","Normal") -> Normal | D6: =VLOOKUP(A6,Dataset!$A:$O,11,0) -> 3 | E6: =IF(D6>=8,"Heavy",IF(D6>=4,"Moderate","Light")) -> Light | F6: =VLOOKUP(A6,Dataset!$A:$O,12,0) -> Fail | G6: =IF(F6="Pass","Pass","Fail") -> Fail
A7: BUG-004 | B7: =VLOOKUP(A7,Dataset!$A:$O,7,0) -> Closed | C7: =IF(VLOOKUP(A7,Dataset!$A:$O,6,0)="High","High Priority","Normal") -> Normal | D7: =VLOOKUP(A7,Dataset!$A:$O,11,0) -> 2 | E7: =IF(D7>=8,"Heavy",IF(D7>=4,"Moderate","Light")) -> Light | F7: =VLOOKUP(A7,Dataset!$A:$O,12,0) -> Pass | G7: =IF(F7="Pass","Pass","Fail") -> Pass
A8: BUG-005 | B8: =VLOOKUP(A8,Dataset!$A:$O,7,0) -> Resolved | C8: =IF(VLOOKUP(A8,Dataset!$A:$O,6,0)="High","High Priority","Normal") -> High Priority | D8: =VLOOKUP(A8,Dataset!$A:$O,11,0) -> 10 | E8: =IF(D8>=8,"Heavy",IF(D8>=4,"Moderate","Light")) -> Heavy | F8: =VLOOKUP(A8,Dataset!$A:$O,12,0) -> Pass | G8: =IF(F8="Pass","Pass","Fail") -> Pass
A9: BUG-006 | B9: =VLOOKUP(A9,Dataset!$A:$O,7,0) -> Open | C9: =IF(VLOOKUP(A9,Dataset!$A:$O,6,0)="High","High Priority","Normal") -> Normal | D9: =VLOOKUP(A9,Dataset!$A:$O,11,0) -> 4 | E9: =IF(D9>=8,"Heavy",IF(D9>=4,"Moderate","Light")) -> Moderate | F9: =VLOOKUP(A9,Dataset!$A:$O,12,0) -> Fail | G9: =IF(F9="Pass","Pass","Fail") -> Fail
A10: BUG-007 | B10: =VLOOKUP(A10,Dataset!$A:$O,7,0) -> Closed | C10: =IF(VLOOKUP(A10,Dataset!$A:$O,6,0)="High","High Priority","Normal") -> Normal | D10: =VLOOKUP(A10,Dataset!$A:$O,11,0) -> 3 | E10: =IF(D10>=8,"Heavy",IF(D10>=4,"Moderate","Light")) -> Light | F10: =VLOOKUP(A10,Dataset!$A:$O,12,0) -> Pass | G10: =IF(F10="Pass","Pass","Fail") -> Pass
A11: BUG-008 | B11: =VLOOKUP(A11,Dataset!$A:$O,7,0) -> Resolved | C11: =IF(VLOOKUP(A11,Dataset!$A:$O,6,0)="High","High Priority","Normal") -> Normal | D11: =VLOOKUP(A11,Dataset!$A:$O,11,0) -> 2 | E11: =IF(D11>=8,"Heavy",IF(D11>=4,"Moderate","Light")) -> Light | F11: =VLOOKUP(A11,Dataset!$A:$O,12,0) -> Pass | G11: =IF(F11="Pass","Pass","Fail") -> Pass
A12: BUG-009 | B12: =VLOOKUP(A12,Dataset!$A:$O,7,0) -> Open | C12: =IF(VLOOKUP(A12,Dataset!$A:$O,6,0)="High","High Priority","Normal") -> High Priority | D12: =VLOOKUP(A12,Dataset!$A:$O,11,0) -> 7 | E12: =IF(D12>=8,"Heavy",IF(D12>=4,"Moderate","Light")) -> Moderate | F12: =VLOOKUP(A12,Dataset!$A:$O,12,0) -> Fail | G12: =IF(F12="Pass","Pass","Fail") -> Fail
A13: BUG-010 | B13: =VLOOKUP(A13,Dataset!$A:$O,7,0) -> Resolved | C13: =IF(VLOOKUP(A13,Dataset!$A:$O,6,0)="High","High Priority","Normal") -> High Priority | D13: =VLOOKUP(A13,Dataset!$A:$O,11,0) -> 6 | E13: =IF(D13>=8,"Heavy",IF(D13>=4,"Moderate","Light")) -> Moderate | F13: =VLOOKUP(A13,Dataset!$A:$O,12,0) -> Pass | G13: =IF(F13="Pass","Pass","Fail") -> Pass
A14: BUG-011 | B14: =VLOOKUP(A14,Dataset!$A:$O,7,0) -> Open | C14: =IF(VLOOKUP(A14,Dataset!$A:$O,6,0)="High","High Priority","Normal") -> Normal | D14: =VLOOKUP(A14,Dataset!$A:$O,11,0) -> 3 | E14: =IF(D14>=8,"Heavy",IF(D14>=4,"Moderate","Light")) -> Light | F14: =VLOOKUP(A14,Dataset!$A:$O,12,0) -> Fail | G14: =IF(F14="Pass","Pass","Fail") -> Fail
A15: BUG-012 | B15: =VLOOKUP(A15,Dataset!$A:$O,7,0) -> Closed | C15: =IF(VLOOKUP(A15,Dataset!$A:$O,6,0)="High","High Priority","Normal") -> Normal | D15: =VLOOKUP(A15,Dataset!$A:$O,11,0) -> 1 | E15: =IF(D15>=8,"Heavy",IF(D15>=4,"Moderate","Light")) -> Light | F15: =VLOOKUP(A15,Dataset!$A:$O,12,0) -> Pass | G15: =IF(F15="Pass","Pass","Fail") -> Pass
... A23: BUG-020 | B23: =VLOOKUP(A23,Dataset!$A:$O,7,0) -> Closed | C23: =IF(VLOOKUP(A23,Dataset!$A:$O,6,0)="High","High Priority","Normal") -> Normal | D23: =VLOOKUP(A23,Dataset!$A:$O,11,0) -> 1 | E23: =IF(D23>=8,"Heavy",IF(D23>=4,"Moderate","Light")) -> Light | F23: =VLOOKUP(A23,Dataset!$A:$O,12,0) -> Pass | G23: =IF(F23="Pass","Pass","Fail") -> Pass
A25: B › AND / OR — Combine multiple conditions inside an IF
A26: Bug_ID | B26: Severity | C26: Status | D26: AND: Critical+Open | E26: OR: Critical/High | F26: AND: Resolved+Pass | G26: Escalate? (nested)
A27: BUG-001 | B27: =VLOOKUP(A27,Dataset!$A:$O,5,0) -> Critical | C27: =VLOOKUP(A27,Dataset!$A:$O,7,0) -> Open | D27: =IF(AND(B27="Critical",C27="Open"),"Yes","No") -> Yes | E27: =IF(OR(B27="Critical",B27="High"),"Yes","No") -> Yes | F27: =IF(AND(C27="Resolved",VLOOKUP(A27,Dataset!$A:$O,12,0)="Pass"),"✅ Done","⏳ Pending") -> ⏳ Pending | G27: =IF(AND(B27="Critical",C27="Open"),"Escalate",IF(AND(B27="High",C27="Open"),"Monitor","OK")) -> Escalate
A28: BUG-002 | B28: =VLOOKUP(A28,Dataset!$A:$O,5,0) -> High | C28: =VLOOKUP(A28,Dataset!$A:$O,7,0) -> Resolved | D28: =IF(AND(B28="Critical",C28="Open"),"Yes","No") -> No | E28: =IF(OR(B28="Critical",B28="High"),"Yes","No") -> Yes | F28: =IF(AND(C28="Resolved",VLOOKUP(A28,Dataset!$A:$O,12,0)="Pass"),"✅ Done","⏳ Pending") -> ✅ Done | G28: =IF(AND(B28="Critical",C28="Open"),"Escalate",IF(AND(B28="High",C28="Open"),"Monitor","OK")) -> OK
A29: BUG-003 | B29: =VLOOKUP(A29,Dataset!$A:$O,5,0) -> Medium | C29: =VLOOKUP(A29,Dataset!$A:$O,7,0) -> Open | D29: =IF(AND(B29="Critical",C29="Open"),"Yes","No") -> No | E29: =IF(OR(B29="Critical",B29="High"),"Yes","No") -> No | F29: =IF(AND(C29="Resolved",VLOOKUP(A29,Dataset!$A:$O,12,0)="Pass"),"✅ Done","⏳ Pending") -> ⏳ Pending | G29: =IF(AND(B29="Critical",C29="Open"),"Escalate",IF(AND(B29="High",C29="Open"),"Monitor","OK")) -> OK
A30: BUG-004 | B30: =VLOOKUP(A30,Dataset!$A:$O,5,0) -> Low | C30: =VLOOKUP(A30,Dataset!$A:$O,7,0) -> Closed | D30: =IF(AND(B30="Critical",C30="Open"),"Yes","No") -> No | E30: =IF(OR(B30="Critical",B30="High"),"Yes","No") -> No | F30: =IF(AND(C30="Resolved",VLOOKUP(A30,Dataset!$A:$O,12,0)="Pass"),"✅ Done","⏳ Pending") -> ⏳ Pending | G30: =IF(AND(B30="Critical",C30="Open"),"Escalate",IF(AND(B30="High",C30="Open"),"Monitor","OK")) -> OK
A31: BUG-005 | B31: =VLOOKUP(A31,Dataset!$A:$O,5,0) -> Critical | C31: =VLOOKUP(A31,Dataset!$A:$O,7,0) -> Resolved | D31: =IF(AND(B31="Critical",C31="Open"),"Yes","No") -> No | E31: =IF(OR(B31="Critical",B31="High"),"Yes","No") -> Yes | F31: =IF(AND(C31="Resolved",VLOOKUP(A31,Dataset!$A:$O,12,0)="Pass"),"✅ Done","⏳ Pending") -> ✅ Done | G31: =IF(AND(B31="Critical",C31="Open"),"Escalate",IF(AND(B31="High",C31="Open"),"Monitor","OK")) -> OK
A32: BUG-006 | B32: =VLOOKUP(A32,Dataset!$A:$O,5,0) -> High | C32: =VLOOKUP(A32,Dataset!$A:$O,7,0) -> Open | D32: =IF(AND(B32="Critical",C32="Open"),"Yes","No") -> No | E32: =IF(OR(B32="Critical",B32="High"),"Yes","No") -> Yes | F32: =IF(AND(C32="Resolved",VLOOKUP(A32,Dataset!$A:$O,12,0)="Pass"),"✅ Done","⏳ Pending") -> ⏳ Pending | G32: =IF(AND(B32="Critical",C32="Open"),"Escalate",IF(AND(B32="High",C32="Open"),"Monitor","OK")) -> Monitor
A33: BUG-007 | B33: =VLOOKUP(A33,Dataset!$A:$O,5,0) -> Medium | C33: =VLOOKUP(A33,Dataset!$A:$O,7,0) -> Closed | D33: =IF(AND(B33="Critical",C33="Open"),"Yes","No") -> No | E33: =IF(OR(B33="Critical",B33="High"),"Yes","No") -> No | F33: =IF(AND(C33="Resolved",VLOOKUP(A33,Dataset!$A:$O,12,0)="Pass"),"✅ Done","⏳ Pending") -> ⏳ Pending | G33: =IF(AND(B33="Critical",C33="Open"),"Escalate",IF(AND(B33="High",C33="Open"),"Monitor","OK")) -> OK
A34: BUG-008 | B34: =VLOOKUP(A34,Dataset!$A:$O,5,0) -> Low | C34: =VLOOKUP(A34,Dataset!$A:$O,7,0) -> Resolved | D34: =IF(AND(B34="Critical",C34="Open"),"Yes","No") -> No | E34: =IF(OR(B34="Critical",B34="High"),"Yes","No") -> No | F34: =IF(AND(C34="Resolved",VLOOKUP(A34,Dataset!$A:$O,12,0)="Pass"),"✅ Done","⏳ Pending") -> ✅ Done | G34: =IF(AND(B34="Critical",C34="Open"),"Escalate",IF(AND(B34="High",C34="Open"),"Monitor","OK")) -> OK
A35: BUG-009 | B35: =VLOOKUP(A35,Dataset!$A:$O,5,0) -> Critical | C35: =VLOOKUP(A35,Dataset!$A:$O,7,0) -> Open | D35: =IF(AND(B35="Critical",C35="Open"),"Yes","No") -> Yes | E35: =IF(OR(B35="Critical",B35="High"),"Yes","No") -> Yes | F35: =IF(AND(C35="Resolved",VLOOKUP(A35,Dataset!$A:$O,12,0)="Pass"),"✅ Done","⏳ Pending") -> ⏳ Pending | G35: =IF(AND(B35="Critical",C35="Open"),"Escalate",IF(AND(B35="High",C35="Open"),"Monitor","OK")) -> Escalate
A36: BUG-010 | B36: =VLOOKUP(A36,Dataset!$A:$O,5,0) -> High | C36: =VLOOKUP(A36,Dataset!$A:$O,7,0) -> Resolved | D36: =IF(AND(B36="Critical",C36="Open"),"Yes","No") -> No | E36: =IF(OR(B36="Critical",B36="High"),"Yes","No") -> Yes | F36: =IF(AND(C36="Resolved",VLOOKUP(A36,Dataset!$A:$O,12,0)="Pass"),"✅ Done","⏳ Pending") -> ✅ Done | G36: =IF(AND(B36="Critical",C36="Open"),"Escalate",IF(AND(B36="High",C36="Open"),"Monitor","OK")) -> OK
A37: BUG-011 | B37: =VLOOKUP(A37,Dataset!$A:$O,5,0) -> Medium | C37: =VLOOKUP(A37,Dataset!$A:$O,7,0) -> Open | D37: =IF(AND(B37="Critical",C37="Open"),"Yes","No") -> No | E37: =IF(OR(B37="Critical",B37="High"),"Yes","No") -> No | F37: =IF(AND(C37="Resolved",VLOOKUP(A37,Dataset!$A:$O,12,0)="Pass"),"✅ Done","⏳ Pending") -> ⏳ Pending | G37: =IF(AND(B37="Critical",C37="Open"),"Escalate",IF(AND(B37="High",C37="Open"),"Monitor","OK")) -> OK
A38: BUG-012 | B38: =VLOOKUP(A38,Dataset!$A:$O,5,0) -> Low | C38: =VLOOKUP(A38,Dataset!$A:$O,7,0) -> Closed | D38: =IF(AND(B38="Critical",C38="Open"),"Yes","No") -> No | E38: =IF(OR(B38="Critical",B38="High"),"Yes","No") -> No | F38: =IF(AND(C38="Resolved",VLOOKUP(A38,Dataset!$A:$O,12,0)="Pass"),"✅ Done","⏳ Pending") -> ⏳ Pending | G38: =IF(AND(B38="Critical",C38="Open"),"Escalate",IF(AND(B38="High",C38="Open"),"Monitor","OK")) -> OK
... A46: BUG-020 | B46: =VLOOKUP(A46,Dataset!$A:$O,5,0) -> Low | C46: =VLOOKUP(A46,Dataset!$A:$O,7,0) -> Closed | D46: =IF(AND(B46="Critical",C46="Open"),"Yes","No") -> No | E46: =IF(OR(B46="Critical",B46="High"),"Yes","No") -> No | F46: =IF(AND(C46="Resolved",VLOOKUP(A46,Dataset!$A:$O,12,0)="Pass"),"✅ Done","⏳ Pending") -> ⏳ Pending | G46: =IF(AND(B46="Critical",C46="Open"),"Escalate",IF(AND(B46="High",C46="Open"),"Monitor","OK")) -> OK

Sheet S4_DateTime_Functions
A1: DATE / TIME FUNCTIONS | Topics: TODAY · NOW · DATE · DATEDIF · NETWORKDAYS · EOMONTH · WEEKNUM
A2: A › TODAY · NOW · DATE — Getting and building dates
A3: TODAY() = today's date (updates daily). NOW() = current date+time. DATE(year,month,day) = build a date from parts.
A4: Formula | B4: Result | C4: Notes
A5: =TODAY() -> 46192 | B5: =TODAY() -> 46192 | C5: Today's date (auto-updates)
A6: =NOW() -> 46192.617 | B6: =NOW() -> 46192.617 | C6: Current date + time
A7: =DATE(2024,3,15) -> 45366 | B7: =DATE(2024,3,15) -> 45366 | C7: Build date: 15-Mar-2024
A8: =YEAR(TODAY()) -> 2026 | B8: =YEAR(TODAY()) -> 2026 | C8: Current year
A9: =MONTH(TODAY()) -> 6 | B9: =MONTH(TODAY()) -> 6 | C9: Current month number
A10: =DAY(TODAY()) -> 19 | B10: =DAY(TODAY()) -> 19 | C10: Day of today
A11: =TODAY()-DATE(2024,1,1) -> 900 | B11: =TODAY()-DATE(2024,1,1) -> 900 | C11: Days elapsed since 1 Jan 2024
A13: B › DATEDIF · NETWORKDAYS · EOMONTH · WEEKNUM — Calculating with dates from Bug records
A14: Bug_ID | B14: Reported | C14: Resolved | D14: Days_Open (DATEDIF) | E14: Work_Days (NETWORKDAYS) | F14: Month_End (EOMONTH) | G14: Week_Num | H14: Status
A15: BUG-001 | B15: =VLOOKUP(A15,Dataset!$A:$O,8,0) -> 45296 | C15: =IFERROR(VLOOKUP(A15,Dataset!$A:$O,9,0),"Open") -> 0 | D15: =IFERROR(DATEDIF(B15,IF(C15="Open",TODAY(),C15),"D"),"—") -> — | E15: =IFERROR(NETWORKDAYS(B15,IF(C15="Open",TODAY(),C15)),"—") -> -32355 | F15: =IFERROR(EOMONTH(B15,0),"—") -> 45322 | G15: =IFERROR(WEEKNUM(B15,2),"—") -> 1 | H15: =VLOOKUP(A15,Dataset!$A:$O,7,0) -> Open
A16: BUG-002 | B16: =VLOOKUP(A16,Dataset!$A:$O,8,0) -> 45297 | C16: =IFERROR(VLOOKUP(A16,Dataset!$A:$O,9,0),"Open") -> 45299 | D16: =IFERROR(DATEDIF(B16,IF(C16="Open",TODAY(),C16),"D"),"—") -> 2 | E16: =IFERROR(NETWORKDAYS(B16,IF(C16="Open",TODAY(),C16)),"—") -> 1 | F16: =IFERROR(EOMONTH(B16,0),"—") -> 45322 | G16: =IFERROR(WEEKNUM(B16,2),"—") -> 1 | H16: =VLOOKUP(A16,Dataset!$A:$O,7,0) -> Resolved
A17: BUG-003 | B17: =VLOOKUP(A17,Dataset!$A:$O,8,0) -> 45298 | C17: =IFERROR(VLOOKUP(A17,Dataset!$A:$O,9,0),"Open") -> 0 | D17: =IFERROR(DATEDIF(B17,IF(C17="Open",TODAY(),C17),"D"),"—") -> — | E17: =IFERROR(NETWORKDAYS(B17,IF(C17="Open",TODAY(),C17)),"—") -> -32355 | F17: =IFERROR(EOMONTH(B17,0),"—") -> 45322 | G17: =IFERROR(WEEKNUM(B17,2),"—") -> 1 | H17: =VLOOKUP(A17,Dataset!$A:$O,7,0) -> Open
A18: BUG-004 | B18: =VLOOKUP(A18,Dataset!$A:$O,8,0) -> 45299 | C18: =IFERROR(VLOOKUP(A18,Dataset!$A:$O,9,0),"Open") -> 45300 | D18: =IFERROR(DATEDIF(B18,IF(C18="Open",TODAY(),C18),"D"),"—") -> 1 | E18: =IFERROR(NETWORKDAYS(B18,IF(C18="Open",TODAY(),C18)),"—") -> 2 | F18: =IFERROR(EOMONTH(B18,0),"—") -> 45322 | G18: =IFERROR(WEEKNUM(B18,2),"—") -> 2 | H18: =VLOOKUP(A18,Dataset!$A:$O,7,0) -> Closed
A19: BUG-005 | B19: =VLOOKUP(A19,Dataset!$A:$O,8,0) -> 45300 | C19: =IFERROR(VLOOKUP(A19,Dataset!$A:$O,9,0),"Open") -> 45302 | D19: =IFERROR(DATEDIF(B19,IF(C19="Open",TODAY(),C19),"D"),"—") -> 2 | E19: =IFERROR(NETWORKDAYS(B19,IF(C19="Open",TODAY(),C19)),"—") -> 3 | F19: =IFERROR(EOMONTH(B19,0),"—") -> 45322 | G19: =IFERROR(WEEKNUM(B19,2),"—") -> 2 | H19: =VLOOKUP(A19,Dataset!$A:$O,7,0) -> Resolved
A20: BUG-006 | B20: =VLOOKUP(A20,Dataset!$A:$O,8,0) -> 45301 | C20: =IFERROR(VLOOKUP(A20,Dataset!$A:$O,9,0),"Open") -> 0 | D20: =IFERROR(DATEDIF(B20,IF(C20="Open",TODAY(),C20),"D"),"—") -> — | E20: =IFERROR(NETWORKDAYS(B20,IF(C20="Open",TODAY(),C20)),"—") -> -32358 | F20: =IFERROR(EOMONTH(B20,0),"—") -> 45322 | G20: =IFERROR(WEEKNUM(B20,2),"—") -> 2 | H20: =VLOOKUP(A20,Dataset!$A:$O,7,0) -> Open
A21: BUG-007 | B21: =VLOOKUP(A21,Dataset!$A:$O,8,0) -> 45302 | C21: =IFERROR(VLOOKUP(A21,Dataset!$A:$O,9,0),"Open") -> 45304 | D21: =IFERROR(DATEDIF(B21,IF(C21="Open",TODAY(),C21),"D"),"—") -> 2 | E21: =IFERROR(NETWORKDAYS(B21,IF(C21="Open",TODAY(),C21)),"—") -> 2 | F21: =IFERROR(EOMONTH(B21,0),"—") -> 45322 | G21: =IFERROR(WEEKNUM(B21,2),"—") -> 2 | H21: =VLOOKUP(A21,Dataset!$A:$O,7,0) -> Closed
A22: BUG-008 | B22: =VLOOKUP(A22,Dataset!$A:$O,8,0) -> 45303 | C22: =IFERROR(VLOOKUP(A22,Dataset!$A:$O,9,0),"Open") -> 45305 | D22: =IFERROR(DATEDIF(B22,IF(C22="Open",TODAY(),C22),"D"),"—") -> 2 | E22: =IFERROR(NETWORKDAYS(B22,IF(C22="Open",TODAY(),C22)),"—") -> 1 | F22: =IFERROR(EOMONTH(B22,0),"—") -> 45322 | G22: =IFERROR(WEEKNUM(B22,2),"—") -> 2 | H22: =VLOOKUP(A22,Dataset!$A:$O,7,0) -> Resolved
A23: BUG-009 | B23: =VLOOKUP(A23,Dataset!$A:$O,8,0) -> 45304 | C23: =IFERROR(VLOOKUP(A23,Dataset!$A:$O,9,0),"Open") -> 0 | D23: =IFERROR(DATEDIF(B23,IF(C23="Open",TODAY(),C23),"D"),"—") -> — | E23: =IFERROR(NETWORKDAYS(B23,IF(C23="Open",TODAY(),C23)),"—") -> -32360 | F23: =IFERROR(EOMONTH(B23,0),"—") -> 45322 | G23: =IFERROR(WEEKNUM(B23,2),"—") -> 2 | H23: =VLOOKUP(A23,Dataset!$A:$O,7,0) -> Open
A24: BUG-010 | B24: =VLOOKUP(A24,Dataset!$A:$O,8,0) -> 45305 | C24: =IFERROR(VLOOKUP(A24,Dataset!$A:$O,9,0),"Open") -> 45307 | D24: =IFERROR(DATEDIF(B24,IF(C24="Open",TODAY(),C24),"D"),"—") -> 2 | E24: =IFERROR(NETWORKDAYS(B24,IF(C24="Open",TODAY(),C24)),"—") -> 2 | F24: =IFERROR(EOMONTH(B24,0),"—") -> 45322 | G24: =IFERROR(WEEKNUM(B24,2),"—") -> 2 | H24: =VLOOKUP(A24,Dataset!$A:$O,7,0) -> Resolved
A25: BUG-011 | B25: =VLOOKUP(A25,Dataset!$A:$O,8,0) -> 45306 | C25: =IFERROR(VLOOKUP(A25,Dataset!$A:$O,9,0),"Open") -> 0 | D25: =IFERROR(DATEDIF(B25,IF(C25="Open",TODAY(),C25),"D"),"—") -> — | E25: =IFERROR(NETWORKDAYS(B25,IF(C25="Open",TODAY(),C25)),"—") -> -32361 | F25: =IFERROR(EOMONTH(B25,0),"—") -> 45322 | G25: =IFERROR(WEEKNUM(B25,2),"—") -> 3 | H25: =VLOOKUP(A25,Dataset!$A:$O,7,0) -> Open
A26: BUG-012 | B26: =VLOOKUP(A26,Dataset!$A:$O,8,0) -> 45307 | C26: =IFERROR(VLOOKUP(A26,Dataset!$A:$O,9,0),"Open") -> 45308 | D26: =IFERROR(DATEDIF(B26,IF(C26="Open",TODAY(),C26),"D"),"—") -> 1 | E26: =IFERROR(NETWORKDAYS(B26,IF(C26="Open",TODAY(),C26)),"—") -> 2 | F26: =IFERROR(EOMONTH(B26,0),"—") -> 45322 | G26: =IFERROR(WEEKNUM(B26,2),"—") -> 3 | H26: =VLOOKUP(A26,Dataset!$A:$O,7,0) -> Closed
... A34: BUG-020 | B34: =VLOOKUP(A34,Dataset!$A:$O,8,0) -> 45315 | C34: =IFERROR(VLOOKUP(A34,Dataset!$A:$O,9,0),"Open") -> 45316 | D34: =IFERROR(DATEDIF(B34,IF(C34="Open",TODAY(),C34),"D"),"—") -> 1 | E34: =IFERROR(NETWORKDAYS(B34,IF(C34="Open",TODAY(),C34)),"—") -> 2 | F34: =IFERROR(EOMONTH(B34,0),"—") -> 45322 | G34: =IFERROR(WEEKNUM(B34,2),"—") -> 4 | H34: =VLOOKUP(A34,Dataset!$A:$O,7,0) -> Closed

Sheet S5_Text_Functions
A1: TEXT FUNCTIONS | Topics: MID · SEARCH · LEFT · RIGHT · TRIM · CLEAN · UPPER · LOWER · PROPER · SUBSTITUTE · DOLLAR · TEXT
A2: A › LEFT · RIGHT · MID · SEARCH — Extract parts of text
A3: Bug_ID | B3: Bug_ID text | C3: LEFT 3 | D3: RIGHT 3 | E3: MID (5,3) = num part | F3: SEARCH 'BUG' | G3: SEARCH '-' pos
A4: BUG-001 | B4: =VLOOKUP(A4,Dataset!$A:$O,1,0) -> BUG-001 | C4: =LEFT(A4,3) -> BUG | D4: =RIGHT(A4,3) -> 001 | E4: =MID(A4,5,3) -> 001 | F4: =SEARCH("BUG",A4) -> 1 | G4: =SEARCH("-",A4) -> 4
A5: BUG-002 | B5: =VLOOKUP(A5,Dataset!$A:$O,1,0) -> BUG-002 | C5: =LEFT(A5,3) -> BUG | D5: =RIGHT(A5,3) -> 002 | E5: =MID(A5,5,3) -> 002 | F5: =SEARCH("BUG",A5) -> 1 | G5: =SEARCH("-",A5) -> 4
A6: BUG-003 | B6: =VLOOKUP(A6,Dataset!$A:$O,1,0) -> BUG-003 | C6: =LEFT(A6,3) -> BUG | D6: =RIGHT(A6,3) -> 003 | E6: =MID(A6,5,3) -> 003 | F6: =SEARCH("BUG",A6) -> 1 | G6: =SEARCH("-",A6) -> 4
A7: BUG-004 | B7: =VLOOKUP(A7,Dataset!$A:$O,1,0) -> BUG-004 | C7: =LEFT(A7,3) -> BUG | D7: =RIGHT(A7,3) -> 004 | E7: =MID(A7,5,3) -> 004 | F7: =SEARCH("BUG",A7) -> 1 | G7: =SEARCH("-",A7) -> 4
A8: BUG-005 | B8: =VLOOKUP(A8,Dataset!$A:$O,1,0) -> BUG-005 | C8: =LEFT(A8,3) -> BUG | D8: =RIGHT(A8,3) -> 005 | E8: =MID(A8,5,3) -> 005 | F8: =SEARCH("BUG",A8) -> 1 | G8: =SEARCH("-",A8) -> 4
A9: BUG-006 | B9: =VLOOKUP(A9,Dataset!$A:$O,1,0) -> BUG-006 | C9: =LEFT(A9,3) -> BUG | D9: =RIGHT(A9,3) -> 006 | E9: =MID(A9,5,3) -> 006 | F9: =SEARCH("BUG",A9) -> 1 | G9: =SEARCH("-",A9) -> 4
A10: BUG-007 | B10: =VLOOKUP(A10,Dataset!$A:$O,1,0) -> BUG-007 | C10: =LEFT(A10,3) -> BUG | D10: =RIGHT(A10,3) -> 007 | E10: =MID(A10,5,3) -> 007 | F10: =SEARCH("BUG",A10) -> 1 | G10: =SEARCH("-",A10) -> 4
A11: BUG-008 | B11: =VLOOKUP(A11,Dataset!$A:$O,1,0) -> BUG-008 | C11: =LEFT(A11,3) -> BUG | D11: =RIGHT(A11,3) -> 008 | E11: =MID(A11,5,3) -> 008 | F11: =SEARCH("BUG",A11) -> 1 | G11: =SEARCH("-",A11) -> 4
A12: BUG-009 | B12: =VLOOKUP(A12,Dataset!$A:$O,1,0) -> BUG-009 | C12: =LEFT(A12,3) -> BUG | D12: =RIGHT(A12,3) -> 009 | E12: =MID(A12,5,3) -> 009 | F12: =SEARCH("BUG",A12) -> 1 | G12: =SEARCH("-",A12) -> 4
A13: BUG-010 | B13: =VLOOKUP(A13,Dataset!$A:$O,1,0) -> BUG-010 | C13: =LEFT(A13,3) -> BUG | D13: =RIGHT(A13,3) -> 010 | E13: =MID(A13,5,3) -> 010 | F13: =SEARCH("BUG",A13) -> 1 | G13: =SEARCH("-",A13) -> 4
A14: BUG-011 | B14: =VLOOKUP(A14,Dataset!$A:$O,1,0) -> BUG-011 | C14: =LEFT(A14,3) -> BUG | D14: =RIGHT(A14,3) -> 011 | E14: =MID(A14,5,3) -> 011 | F14: =SEARCH("BUG",A14) -> 1 | G14: =SEARCH("-",A14) -> 4
A15: BUG-012 | B15: =VLOOKUP(A15,Dataset!$A:$O,1,0) -> BUG-012 | C15: =LEFT(A15,3) -> BUG | D15: =RIGHT(A15,3) -> 012 | E15: =MID(A15,5,3) -> 012 | F15: =SEARCH("BUG",A15) -> 1 | G15: =SEARCH("-",A15) -> 4
... A23: BUG-020 | B23: =VLOOKUP(A23,Dataset!$A:$O,1,0) -> BUG-020 | C23: =LEFT(A23,3) -> BUG | D23: =RIGHT(A23,3) -> 020 | E23: =MID(A23,5,3) -> 020 | F23: =SEARCH("BUG",A23) -> 1 | G23: =SEARCH("-",A23) -> 4
A25: B › TRIM · CLEAN · UPPER · LOWER · PROPER — Clean and transform text case
A26: Bug_ID | B26: Raw_Text (messy) | C26: TRIM | D26: UPPER | E26: LOWER | F26: PROPER | G26: CLEAN
A27: BUG-001 | B27: critical BUG | C27: =TRIM(B27) -> critical BUG | D27: =UPPER(TRIM(B27)) -> CRITICAL BUG | E27: =LOWER(TRIM(B27)) -> critical bug | F27: =PROPER(TRIM(B27)) -> Critical Bug | G27: =CLEAN(TRIM(B27)) -> critical BUG
A28: BUG-002 | B28: ALPHA project | C28: =TRIM(B28) -> ALPHA project | D28: =UPPER(TRIM(B28)) -> ALPHA PROJECT | E28: =LOWER(TRIM(B28)) -> alpha project | F28: =PROPER(TRIM(B28)) -> Alpha Project | G28: =CLEAN(TRIM(B28)) -> ALPHA project
A29: BUG-003 | B29: login MODULE | C29: =TRIM(B29) -> login MODULE | D29: =UPPER(TRIM(B29)) -> LOGIN MODULE | E29: =LOWER(TRIM(B29)) -> login module | F29: =PROPER(TRIM(B29)) -> Login Module | G29: =CLEAN(TRIM(B29)) -> login MODULE
A30: BUG-004 | B30: beta DASHBOARD | C30: =TRIM(B30) -> beta DASHBOARD | D30: =UPPER(TRIM(B30)) -> BETA DASHBOARD | E30: =LOWER(TRIM(B30)) -> beta dashboard | F30: =PROPER(TRIM(B30)) -> Beta Dashboard | G30: =CLEAN(TRIM(B30)) -> beta DASHBOARD
A31: BUG-005 | B31: PAYMENTS module | C31: =TRIM(B31) -> PAYMENTS module | D31: =UPPER(TRIM(B31)) -> PAYMENTS MODULE | E31: =LOWER(TRIM(B31)) -> payments module | F31: =PROPER(TRIM(B31)) -> Payments Module | G31: =CLEAN(TRIM(B31)) -> PAYMENTS module
A32: BUG-006 | B32: gamma search | C32: =TRIM(B32) -> gamma search | D32: =UPPER(TRIM(B32)) -> GAMMA SEARCH | E32: =LOWER(TRIM(B32)) -> gamma search | F32: =PROPER(TRIM(B32)) -> Gamma Search | G32: =CLEAN(TRIM(B32)) -> gamma search
A33: BUG-007 | B33: REPORTS module | C33: =TRIM(B33) -> REPORTS module | D33: =UPPER(TRIM(B33)) -> REPORTS MODULE | E33: =LOWER(TRIM(B33)) -> reports module | F33: =PROPER(TRIM(B33)) -> Reports Module | G33: =CLEAN(TRIM(B33)) -> REPORTS module
A34: BUG-008 | B34: QA environment | C34: =TRIM(B34) -> QA environment | D34: =UPPER(TRIM(B34)) -> QA ENVIRONMENT | E34: =LOWER(TRIM(B34)) -> qa environment | F34: =PROPER(TRIM(B34)) -> Qa Environment | G34: =CLEAN(TRIM(B34)) -> QA environment
A35: BUG-009 | B35: staging BUILD | C35: =TRIM(B35) -> staging BUILD | D35: =UPPER(TRIM(B35)) -> STAGING BUILD | E35: =LOWER(TRIM(B35)) -> staging build | F35: =PROPER(TRIM(B35)) -> Staging Build | G35: =CLEAN(TRIM(B35)) -> staging BUILD
A36: BUG-010 | B36: PRODUCTION env | C36: =TRIM(B36) -> PRODUCTION env | D36: =UPPER(TRIM(B36)) -> PRODUCTION ENV | E36: =LOWER(TRIM(B36)) -> production env | F36: =PROPER(TRIM(B36)) -> Production Env | G36: =CLEAN(TRIM(B36)) -> PRODUCTION env
A38: C › SUBSTITUTE · DOLLAR · TEXT · CONCATENATE — Replace text, format numbers as text, join strings
A39: Bug_ID | B39: Bug_ID original | C39: SUBSTITUTE BUG→DEF | D39: Hours | E39: DOLLAR format | F39: TEXT date | G39: CONCAT: ID+Project
A40: BUG-001 | B40: =VLOOKUP(A40,Dataset!$A:$O,1,0) -> BUG-001 | C40: =SUBSTITUTE(B40,"BUG","DEF") -> DEF-001 | D40: =VLOOKUP(A40,Dataset!$A:$O,11,0) -> 8 | E40: =DOLLAR(D40,2) -> ₹ 8.00 | F40: =TEXT(VLOOKUP(A40,Dataset!$A:$O,8,0),"DD-MMM-YYYY") -> 05-Jan-2024 | G40: =CONCATENATE(A40," | ",VLOOKUP(A40,Dataset!$A:$O,2,0)) -> BUG-001 | Alpha
A41: BUG-002 | B41: =VLOOKUP(A41,Dataset!$A:$O,1,0) -> BUG-002 | C41: =SUBSTITUTE(B41,"BUG","DEF") -> DEF-002 | D41: =VLOOKUP(A41,Dataset!$A:$O,11,0) -> 5 | E41: =DOLLAR(D41,2) -> ₹ 5.00 | F41: =TEXT(VLOOKUP(A41,Dataset!$A:$O,8,0),"DD-MMM-YYYY") -> 06-Jan-2024 | G41: =CONCATENATE(A41," | ",VLOOKUP(A41,Dataset!$A:$O,2,0)) -> BUG-002 | Alpha
A42: BUG-003 | B42: =VLOOKUP(A42,Dataset!$A:$O,1,0) -> BUG-003 | C42: =SUBSTITUTE(B42,"BUG","DEF") -> DEF-003 | D42: =VLOOKUP(A42,Dataset!$A:$O,11,0) -> 3 | E42: =DOLLAR(D42,2) -> ₹ 3.00 | F42: =TEXT(VLOOKUP(A42,Dataset!$A:$O,8,0),"DD-MMM-YYYY") -> 07-Jan-2024 | G42: =CONCATENATE(A42," | ",VLOOKUP(A42,Dataset!$A:$O,2,0)) -> BUG-003 | Beta
A43: BUG-004 | B43: =VLOOKUP(A43,Dataset!$A:$O,1,0) -> BUG-004 | C43: =SUBSTITUTE(B43,"BUG","DEF") -> DEF-004 | D43: =VLOOKUP(A43,Dataset!$A:$O,11,0) -> 2 | E43: =DOLLAR(D43,2) -> ₹ 2.00 | F43: =TEXT(VLOOKUP(A43,Dataset!$A:$O,8,0),"DD-MMM-YYYY") -> 08-Jan-2024 | G43: =CONCATENATE(A43," | ",VLOOKUP(A43,Dataset!$A:$O,2,0)) -> BUG-004 | Beta
A44: BUG-005 | B44: =VLOOKUP(A44,Dataset!$A:$O,1,0) -> BUG-005 | C44: =SUBSTITUTE(B44,"BUG","DEF") -> DEF-005 | D44: =VLOOKUP(A44,Dataset!$A:$O,11,0) -> 10 | E44: =DOLLAR(D44,2) -> ₹ 10.00 | F44: =TEXT(VLOOKUP(A44,Dataset!$A:$O,8,0),"DD-MMM-YYYY") -> 09-Jan-2024 | G44: =CONCATENATE(A44," | ",VLOOKUP(A44,Dataset!$A:$O,2,0)) -> BUG-005 | Alpha
A45: BUG-006 | B45: =VLOOKUP(A45,Dataset!$A:$O,1,0) -> BUG-006 | C45: =SUBSTITUTE(B45,"BUG","DEF") -> DEF-006 | D45: =VLOOKUP(A45,Dataset!$A:$O,11,0) -> 4 | E45: =DOLLAR(D45,2) -> ₹ 4.00 | F45: =TEXT(VLOOKUP(A45,Dataset!$A:$O,8,0),"DD-MMM-YYYY") -> 10-Jan-2024 | G45: =CONCATENATE(A45," | ",VLOOKUP(A45,Dataset!$A:$O,2,0)) -> BUG-006 | Gamma
A46: BUG-007 | B46: =VLOOKUP(A46,Dataset!$A:$O,1,0) -> BUG-007 | C46: =SUBSTITUTE(B46,"BUG","DEF") -> DEF-007 | D46: =VLOOKUP(A46,Dataset!$A:$O,11,0) -> 3 | E46: =DOLLAR(D46,2) -> ₹ 3.00 | F46: =TEXT(VLOOKUP(A46,Dataset!$A:$O,8,0),"DD-MMM-YYYY") -> 11-Jan-2024 | G46: =CONCATENATE(A46," | ",VLOOKUP(A46,Dataset!$A:$O,2,0)) -> BUG-007 | Gamma
A47: BUG-008 | B47: =VLOOKUP(A47,Dataset!$A:$O,1,0) -> BUG-008 | C47: =SUBSTITUTE(B47,"BUG","DEF") -> DEF-008 | D47: =VLOOKUP(A47,Dataset!$A:$O,11,0) -> 2 | E47: =DOLLAR(D47,2) -> ₹ 2.00 | F47: =TEXT(VLOOKUP(A47,Dataset!$A:$O,8,0),"DD-MMM-YYYY") -> 12-Jan-2024 | G47: =CONCATENATE(A47," | ",VLOOKUP(A47,Dataset!$A:$O,2,0)) -> BUG-008 | Alpha
A48: BUG-009 | B48: =VLOOKUP(A48,Dataset!$A:$O,1,0) -> BUG-009 | C48: =SUBSTITUTE(B48,"BUG","DEF") -> DEF-009 | D48: =VLOOKUP(A48,Dataset!$A:$O,11,0) -> 7 | E48: =DOLLAR(D48,2) -> ₹ 7.00 | F48: =TEXT(VLOOKUP(A48,Dataset!$A:$O,8,0),"DD-MMM-YYYY") -> 13-Jan-2024 | G48: =CONCATENATE(A48," | ",VLOOKUP(A48,Dataset!$A:$O,2,0)) -> BUG-009 | Beta
A49: BUG-010 | B49: =VLOOKUP(A49,Dataset!$A:$O,1,0) -> BUG-010 | C49: =SUBSTITUTE(B49,"BUG","DEF") -> DEF-010 | D49: =VLOOKUP(A49,Dataset!$A:$O,11,0) -> 6 | E49: =DOLLAR(D49,2) -> ₹ 6.00 | F49: =TEXT(VLOOKUP(A49,Dataset!$A:$O,8,0),"DD-MMM-YYYY") -> 14-Jan-2024 | G49: =CONCATENATE(A49," | ",VLOOKUP(A49,Dataset!$A:$O,2,0)) -> BUG-010 | Beta
...
